Workbook

Sheet Instructions
A1: Costco DAS Link Budgets -- Off-Air, ADRF SDR and CommScope ERA
A3: Purpose: | B3: To record and validate donor signals at the bottom end of the donor line
B4: To tell the commissioning team what attenuation and parameter values to apply
A6: Instructions: | B6: Only use EXPECTATIONS and COMMISSIONING tabs. You shouldn't need to look at the other tabs.
B7: Designer fills in blue cells on both tabs, and gives this to the Commissioning Team.
B8: On site, Commissioning Team fills in the green cells, and reads recommended values.
B10: All loss figures must be expressed as a negative value
B12: Formatting:
B14: -2 | C14: Default value
B15: -2 | C15: Designer to fill in
B16: -2 | C16: Commissioner to fill in
B17: -2 | C17: Calculated value/recommendation
B19: Red Text | C19: Reference value. Do not sum in link budget.
B21: 44 | C21: Sum of line items above (Downlink)
B23: 44 | C23: Sum of line items below (Uplink)
B25: OPT! | C25: Optimization Parameter!
B26: OTA | C26: Over the air
B27: SDR | C27: ADRF SDR repeater
B28: ERA | C28: CommScope ERA active DAS

Sheet EXPECTATIONS
A1: Expected KPIs in Donor Line
A3: Instructions:
A4: Designer fills in table below with original rooftop readings. | K4: -2 | L4: Default value
A5: Commissioner measures KPIs in donor cable in head-end room (do not include any attenuators for measurement). Enter into table below. | K5: -2 | L5: Designer to fill in
K6: -2 | L6: Commissioner to fill in
A7: "Deltas" columns will calculate the differences. Any values out of expected range will turn red. | K7: -2 | L7: Calculated value/recommendation
A8: Troubleshoot any values that do not meet expectations.
O9: NOTES:
O10: We expect RSRP in the head-end to be approximately (20-5=) 15 dB greater than the RSRP measured on the roof (without antenna gain), because the donor antenna has about 20 dB of gain, and the donor cable has about 5 dB of loss.
C11: Original Rooftop Readings | F11: Expected values in H.E.R. donor cable | I11: Actual measured values in H.E.R. donor cable | L11: Deltas: Measured vs. Expected
A12: Operator | B12: Channel | C12: PCI | D12: RSRP without antenna gain | E12: Max SINR | F12: PCI | G12: RSRP in head-end (donor cable) | H12: Max SINR | I12: PCI | J12: RSRP in head-end (donor cable) | K12: Max SINR | L12: RSRP | M12: SINR
A13: Bell/Telus | B13: LTE 1900 | F13: =IF(C13="","",C13) | G13: =IF(D13="","",D13+$C$22) | H13: =IF(E13="","",E13+$C$23) | L13: =IF(J13="","",J13-G13) | M13: =IF(K13="","",K13-E13)
A14: Bell/Telus | B14: LTE 2100 | F14: =IF(C14="","",C14) | G14: =IF(D14="","",D14+$C$22) | H14: =IF(E14="","",E14+$C$23) | L14: =IF(J14="","",J14-G14) | M14: =IF(K14="","",K14-E14)
A15: Bell/Telus | B15: LTE 2600 | F15: =IF(C15="","",C15) | G15: =IF(D15="","",D15+$C$22) | H15: =IF(E15="","",E15+$C$23) | L15: =IF(J15="","",J15-G15) | M15: =IF(K15="","",K15-E15) | O15: We expect SINR in the head-end to be approximately equal to the SINR measured on the roof.
A16: Rogers | B16: LTE 1900 | F16: =IF(C16="","",C16) | G16: =IF(D16="","",D16+$C$22) | H16: =IF(E16="","",E16+$C$23) | L16: =IF(J16="","",J16-G16) | M16: =IF(K16="","",K16-E16)
A17: Rogers | B17: LTE 2100 | F17: =IF(C17="","",C17) | G17: =IF(D17="","",D17+$C$22) | H17: =IF(E17="","",E17+$C$23) | L17: =IF(J17="","",J17-G17) | M17: =IF(K17="","",K17-E17)
A18: Rogers | B18: LTE 2600 | F18: =IF(C18="","",C18) | G18: =IF(D18="","",D18+$C$22) | H18: =IF(E18="","",E18+$C$23) | L18: =IF(J18="","",J18-G18) | M18: =IF(K18="","",K18-E18)
C22: 15 | D22: dB Donor antenna gain + donor line cable losses (not including attenuators)
C23: 0 | D23: dB SINR gain or loss between rooftop and head-end room

Sheet COMMISSIONING
A1: Commissioning Parameters
A2: NOTE: All attenuation and loss values must be negative
G3: Responsible | H3: NOTES
B4: Number of RANs (1 or 2) | C4: 1 | G4: Designer | H4: Also equals number of repeaters in H.E.R.
A6: Operator #1: Bell
C7: LTE-1900 | D7: LTE-2100 | E7: LTE-2600 | F7: Unit | G7: Responsible | H7: NOTES
B8: LTE channel bandwidth | C8: 20 | D8: 15 | E8: 20 | F8: MHz | G8: Designer
B10: Donor Signal Measurements
B11: Downlink donor signal RSRP in head-end | C11: -50 | D11: -85 | E11: -90 | F11: dBm RSRP | G11: Commis-sioner | H11: Measured in the head-end room, at the end of the donor cable. At the point between the donor line and the SDR combiner "ANT" (Antenna) port. Do not include any physical attenuators in measurement. Measure the RSRP of one LTE channel.
B13: Physical Attenuators
B14: Recommended PHYS attenuation between donor line and SDR amplifier card | C14: ='Bellus 1900'!C17 -> -47 | D14: ='Bellus 2100'!C17 -> -20 | E14: ='Bellus 2600'!C17 -> -16 | F14: dB | G14: Calculated | H14: If all bands require some attenuation, recommend putting some in the common donor line and some on each amplifier card input.
B15: Actual PHYS attenuation between donor line and SDR amplifier card (Attenuation values must be negative!) | C15: -40 | D15: -23 | E15: -20 | F15: dB | G15: Commis-sioner | H15: Get as close as you can by combining physical attenuators. Do not go over.
B17: SDR Parameters
B18: AGC | C18: OFF | D18: =C18 -> OFF | E18: =D18 -> OFF | G18: Designer | H18: AGC should always be off for LTE & 5G, per ADRF
B19: Downlink Gain (Max) | C19: 90 | D19: =C19 -> 90 | E19: =D19 -> 90 | F19: dB | G19: Designer | H19: Property of SDR amplifier module
B20: Uplink Gain (Max) | C20: 90 | D20: =C20 -> 90 | E20: =D20 -> 90 | F20: dB | G20: Designer | H20: Property of SDR amplifier module
B21: Recommended DL Gain setting | C21: ='Bellus 1900'!C23 -> 72
B22: Recommended UL Gain | C22: =C21 -> 72
B23: Actual Downlink Gain setting | C23: =C21 -> 72 | F23: dB | G23: Commissioner
B24: Actual Uplink Gain setting | C24: =C22 -> 72 | F24: dB | G24: Commissioner
B25: SDR DL ALC setting | C25: 13 | D25: =C25 -> 13 | E25: =D25 -> 13 | F25: dBm | G25: Designer | H25: Default value per design
B26: SDR DL ALC Offset | C26: 15 | D26: =C26 -> 15 | E26: =D26 -> 15 | F26: dBm | G26: Designer | H26: Default value per design
B28: ERA Parameters
B29: Max Tx power, DL and UL (CAPM, RFD) | C29: 27 | D29: =C29 -> 27 | E29: =D29 -> 27 | F29: dBm | G29: Designer | H29: DL: per spec sheet. UL: assumption.
B30: Max system gain, DL, UL (CAPM) | C30: 36 | D30: =C30 -> 36 | E30: =D30 -> 36 | F30: dB | G30: Designer | H30: Per spec sheet
B31: Recommended ERA RFD Uplink Gain Offset Setting [integer] | C31: ='Bellus 1900'!G6 -> 7.016116 | D31: ='Bellus 2100'!G6 -> 2.0205999 | E31: ='Bellus 2600'!G6 -> 2.0205999 | F31: dB | G31: Calculated | H31: Positive means more UL than DL gain. Negative means less UL than DL gain.
B32: Actual ERA RFD Uplink Gain Offset Setting [integer] | C32: 7 | D32: 2 | E32: 2 | F32: dB | G32: Commis-sioner | H32: Record the values that you configured in ERA.
B34: Uplink Noise
B35: Expected UL noise power out of ERA RFD port | C35: ='Bellus 1900'!K23 -> -67.777028 | D35: ='Bellus 2100'!K23 -> -72.781512 | E35: ='Bellus 2600'!K23 -> -70.781512 | F35: dBm | G35: Calculated
B36: Measured UL noise power out of ERA RFD port | F36: dBm | G36: Commis-sioner | H36: Measure this with CAPM RF ports terminated, ERA amplifiers active.
B38: UL noise power out of SDR combiner port (all bands) | C38: =10*LOG(10^('Bellus 1900'!K15/10)+10^('Bellus 2100'!K15/10)+10^('Bellus 2600'!K15/10)) -> 20.369488 | D38: dBm Predicted | F38: dBm Measured | G38: Commis-sioner | H38: Measure this with CAPM RF ports terminated, ERA amplifiers active, and SDR amplifiers active.
B40: Default Values
B41: Number of CAPMs (2 or 3) | C41: 2 | D41: =C41 -> 2 | E41: =C41 -> 2 | F41: count | G41: Designer | H41: Check design file
B42: Lowest predicted RSRP in iBwave Design | C42: -95 | D42: -96 | E42: -99 | F42: dBm RSRP | G42: Designer | H42: Check design file
B43: CAPM Tx power/band (spec sheet) | C43: 30 | D43: 30 | E43: 31 | F43: dBm | G43: Designer | H43: Per spec sheet
B44: CAPM Tx power/band/operator | C44: =C43-10*LOG($C$4) -> 30 | D44: =D43-10*LOG($C$4) -> 30 | E44: =E43-10*LOG($C$4) -> 31 | F44: dBm | G44: Calculated | H44: Based on number of RANs (Operators), above
B45: Physical attenuator, SDR-to-ERA | C45: -1e-06 | D45: -1e-06 | E45: -1e-06 | F45: dB | G45: Designer | H45: Design decision
B46: SDR-to-ERA loss (cable, combining, etc.) | C46: -6 | D46: =C46 -> -6 | E46: =C46 -> -6 | F46: dB | G46: Designer | H46: Per observation
B47: Max pathloss from CAPM to UE | C47: =-(C44-C42-10*LOG(60*C8)) -> -94.208188 | D47: =-(D44-D42-10*LOG(60*D8)) -> -96.457575 | E47: =-(E44-E42-10*LOG(60*E8)) -> -99.208188 | F47: dB | G47: Calculated | H47: -(CAPM Tx power -3dB (two operators) - lowest predicted RSRP in iBwave - 10Log(60*BW(MHz)) (converts RSRP to RSSI))
B48: EIRP from UE | C48: 24 | D48: =C48 -> 24 | E48: =C48 -> 24 | F48: dBm | G48: Designer | H48: Per spec sheet
...

Sheet Bellus 1900
A1: Costco DAS Link Budgets -- Off-Air, ADRF SDR and CommScope ERA | G1: -2 | H1: Reference value
B3: DOWNLINK | F3: UPLINK Signal (worst case) | J3: NOISE
A4: Index | B4: Item | C4: Value | D4: Unit | G4: Value | H4: Unit | K4: Value | L4: Unit
A5: OTA | B5: Band & Technology | C5: =COMMISSIONING!C7 -> LTE-1900 | J5: Noise Rise at BTS due to DAS | K5: =K42 -> 0.96999727 | L5: dB
A6: OTA | B6: Channel BW | C6: =COMMISSIONING!C8 -> 20 | D6: MHz | F6: Recommended UL Gain Offset: | G6: =(K37-6)-K39+G35 -> 7.016116 | H6: dB
A7: OTA | B7: BTS radio Tx Power, comp. channel power | C7: 40 | D7: W | J7: UL Noise Power at Donor sector BTS radio | K7: =K12+K14+K15 -> -107.00582 | L7: dBm
A8: OTA | B8: BTS radio Tx Power, comp. channel power | C8: =10*LOG(C7)+30 -> 46.0206 | D8: dBm | F8: Max UL SINR, worst-case UE (traffic not considered) | G8: =G9-K37 -> 15.750613 | H8: dB
A9: OTA | F9: UL RSSI at Donor sector BTS radio | G9: =G12+G14+G15 -> -85.239087 | H9: dBm
A10: OTA | B10: Donor RSRP in donor cable (head-end room) | C10: =COMMISSIONING!C11 -> -50 | D10: dBm RSRP
A11: OTA
A12: OTA | B12: RSRP to max RSSI conversion factor | C12: =10*LOG(60*C6) -> 30.791812 | D12: dB | F12: Pathloss, H.E.R. to Donor sector radio | G12: =C14 -> -65.228787 | H12: dB | J12: Pathloss, H.E.R. to Donor sector radio | K12: =G12 -> -65.228787 | L12: dB
A13: OTA | B13: Max donor RSSI in donor cable (comp. ch pwr) | C13: =C12+C10 -> -19.208188 | D13: dBm RSSI
A14: OTA | B14: Pathloss, Donor sector radio to H.E.R. | C14: =-(C8-C13) -> -65.228787 | D14: dB | F14: Physical attenuator on SDR | G14: =C18 -> -40 | H14: dB | J14: Physical attenuator on SDR amp Donor port | K14: =G14 -> -40 | L14: dB
A15: OTA | F15: UL composite channel power out of SDR | G15: =MIN(SUM(G18:G19),COMMISSIONING!C29) -> 19.9897 | H15: dBm | J15: UL Noise power out of SDR | K15: =SUM(K17:K19) -> -1.7770286 | L15: dBm
A16: OTA | B16: TARGET DL Signal going into SDR (RSSI)(not used) | C16: =C22-C21+2 -> -75 | D16: dBm
A17: OTA | B17: Optimal PHYS attenuation before SDR amp | C17: =ROUND(C22-C13-COMMISSIONING!C29+G19,0) -> -47 | D17: dB
A18: OTA | B18: Actual PHYS attenuation before SDR amp | C18: =COMMISSIONING!C15 -> -40 | D18: dB | F18: SDR UL Gain | G18: =COMMISSIONING!C24 -> 72 | H18: dBm | J18: SDR UL Gain | K18: =G18 -> 72 | L18: dBm
A19: OTA | B19: EXPECTED DL Signal going into SDR (RSSI) | C19: =C13+C18 -> -59.208188 | D19: dBm | F19: UL composite channel power into SDR | G19: =SUM(G20:G23) -> -52.0103 | H19: dBm | J19: UL Noise power into SDR | K19: =SUM(K20:K23) -> -73.777029 | L19: dBm
A20: OTA
A21: OTA | B21: SDR Max Gain (SDR-24 amplifier card) | C21: =COMMISSIONING!C19 -> 90 | D21: dB | F21: Physical attenuator, SDR-to-ERA | G21: =C26 -> -1e-06 | H21: dB | J21: Physical attenuator, SDR-to-ERA | K21: =G21 -> -1e-06 | L21: dB
A22: OTA | B22: SDR DL ALC set point | C22: =COMMISSIONING!C25 -> 13 | D22: dBm | E22: OPT! | F22: SDR-to-ERA loss (cable, combining, etc.) | G22: =C27 -> -6 | H22: dB | J22: Cable loss, SDR-to-ERA | K22: =G22 -> -6 | L22: dB
A23: OTA | B23: DL Gain (dynamically set by ALC) | C23: =MIN(ROUND(C22-C19,0),C21) -> 72 | D23: dB | F23: UL TSSI out of RFD Port | G23: =SUM(G25:G27) -> -46.010299 | H23: dBm | J23: UL Noise power out of RFD Port | K23: =SUM(K24:K29) -> -67.777028 | L23: dBm
A24: OTA | B24: SDR DL transmit power in band (ALC set point) | C24: =C19+C23 -> 12.791812 | D24: dBm
F25: ERA System Uplink Gain (from below box) | G25: =G40 -> 24.197889 | H25: dB | J25: ERA System Uplink Gain | K25: =G25 -> 24.197889 | L25: dB
B26: Physical attenuator, SDR-to-ERA | C26: =COMMISSIONING!C45 -> -1e-06 | D26: dB | E26: OPT!
A27: ERA | B27: SDR-to-ERA loss (cable, combining, etc.) | C27: =COMMISSIONING!C46 -> -6 | D27: dB | E27: Check | F27: UL RSSI at CAPM | G27: =SUM(G28:G29) -> -70.208188 | H27: dBm | J27: Total DAS system Noise Figure (from below) | K27: =K60 -> 9.0147838 | L27: dB
A28: ERA | B28: DL Signal into ERA RFD port | C28: =SUM(C24,C26:C27) -> 6.7918115 | D28: dBm | F28: Pathloss + DAS Loss, UE to CAPM | G28: =C33 -> -94.208188 | H28: dB
F29: EIRP from UE | G29: =COMMISSIONING!C48 -> 24 | H29: dBm | J29: Thermal Noise of CAPM in channel | K29: =-174 + 10*LOG(C6)+60 -> -100.9897 | L29: dBm
A30: ERA | B30: DL composite Tx power /channel @ CAPM | C30: =MIN(C28+COMMISSIONING!C30,COMMISSIONING!C29) -> 27 | D30: dBm | E30: Check
A31: ERA | B31: DL Gain (dynamically set by Auto Gain Setting) | C31: =C30-C28 -> 20.208189 | D31: dB
A32: ERA
A33: ERA | B33: Passive DAS loss + Pathloss to UE | C33: =COMMISSIONING!C47 -> -94.208188 | D33: dB | F33: Calculation of ERA System Uplink Gain: | J33: Calculation of DAS noise's impact on BTS noise floor:
A34: ERA | B34: Max composite channel RSSI at UE | C34: =C30+C33 -> -67.208188 | D34: dBm
A35: ERA | B35: RSRP at UE | C35: =C34-C12 -> -98 | D35: dBm RSRP | F35: ERA RFD Uplink Gain Offset Setting [integer] | G35: =COMMISSIONING!C32 -> 7 | H35: dB | J35: BTS Thermal Noise in channel | K35: =K29 -> -100.9897 | L35: dBm
F36: ERA CAN Reduction = 10.Log(#APs) | G36: =-10*LOG(G37) -> -3.0103 | H36: dB | J36: BTS NF | K36: =COMMISSIONING!C49 -> 0 | L36: dB
F37: ERA Number of CAPMs [integer] | G37: =COMMISSIONING!C41 -> 2 | H37: # | J37: BTS Noise Floor | K37: =SUM(K35:K36) -> -100.9897 | L37: dBm
F38: ERA Baseline UL Gain = DL Gain | G38: =C31 -> 20.208189 | H38: dB
J39: DAS UL RSSI at BTS radio | K39: =K7 -> -107.00582 | L39: dBm
F40: ERA System Uplink Gain | G40: =G38+G36+G35 -> 24.197889 | H40: dB | J40: BTS Noise Floor with DAS UL Noise | K40: =10*LOG(10^(K37/10)+10^(K39/10)) -> -100.0197 | L40: dBm
J42: Noise Rise at BTS due to DAS | K42: =K40-K37 -> 0.96999727 | L42: dB
...

Sheet Bellus 2100
A1: Costco DAS Link Budgets -- Off-Air, ADRF SDR and CommScope ERA | G1: -2 | H1: Reference value
B3: DOWNLINK | F3: UPLINK Signal (worst case) | J3: NOISE
A4: Index | B4: Item | C4: Value | D4: Unit | G4: Value | H4: Unit | K4: Value | L4: Unit
A5: OTA | B5: Band & Technology | C5: =COMMISSIONING!D7 -> LTE-2100 | J5: Noise Rise at BTS due to DAS | K5: =K42 -> 0.96910013 | L5: dB
A6: OTA | B6: Channel BW | C6: =COMMISSIONING!D8 -> 15 | D6: MHz | F6: Recommended UL Gain Offset: | G6: =(K37-6)-K39+G35 -> 2.0205999 | H6: dB
A7: OTA | B7: BTS radio Tx Power, comp. channel power | C7: 40 | D7: W | J7: UL Noise Power at Donor sector BTS radio | K7: =K12+K14+K15 -> -108.25969 | L7: dBm
A8: OTA | B8: BTS radio Tx Power, comp. channel power | C8: =10*LOG(C7)+30 -> 46.0206 | D8: dBm | F8: Max possible UL SINR (not considering traffic) | G8: =G9-K37 -> 9.7506126 | H8: dB
A9: OTA | F9: UL RSSI at Donor sector BTS radio | G9: =G12+G14+G15 -> -92.488475 | H9: dBm
A10: OTA | B10: Donor RSRP in donor cable (head-end room) | C10: =COMMISSIONING!D11 -> -85 | D10: dBm RSRP
A11: OTA
A12: OTA | B12: RSRP to max RSSI conversion factor | C12: =10*LOG(60*C6) -> 29.542425 | D12: dB | F12: Pathloss, H.E.R. to Donor sector radio | G12: =C14 -> -101.47817 | H12: dB | J12: Pathloss, H.E.R. to Donor sector radio | K12: =G12 -> -101.47817 | L12: dB
A13: OTA | B13: Max donor RSSI in donor cable (comp. ch pwr) | C13: =C12+C10 -> -55.457575 | D13: dBm RSSI
A14: OTA | B14: Pathloss, Donor sector radio to H.E.R. | C14: =-(C8-C13) -> -101.47817 | D14: dB | F14: Physical attenuator on SDR | G14: =C18 -> -23 | H14: dB | J14: Physical attenuator on SDR amp Donor port | K14: =G14 -> -23 | L14: dB
A15: OTA | F15: UL composite channel power out of SDR | G15: =SUM(G18:G19) -> 31.9897 | H15: dBm | J15: UL Noise power out of SDR | K15: =SUM(K17:K19) -> 16.218487 | L15: dBm
A16: OTA | B16: TARGET DL Signal going into SDR (RSSI) | C16: =C22-C21+2 -> -75 | D16: dBm
A17: OTA | B17: Required PHYS attenuation before SDR amp | C17: =ROUND(C16-C13,0) -> -20 | D17: dB | J17: SDR NF | K17: =COMMISSIONING!D51 -> 5 | L17: dB
A18: OTA | B18: Actual PHYS attenuation before SDR amp | C18: =COMMISSIONING!D15 -> -23 | D18: dB | F18: SDR UL Gain (same as DL, set by AGC) | G18: =C23 -> 90 | H18: dBm | J18: SDR UL Gain (same as DL, set by AGC) | K18: =G18 -> 90 | L18: dBm
A19: OTA | B19: EXPECTED DL Signal going into SDR (RSSI) | C19: =C13+C18 -> -78.457575 | D19: dBm | F19: UL composite channel power into SDR | G19: =SUM(G20:G23) -> -58.0103 | H19: dBm | J19: UL Noise power into SDR | K19: =SUM(K20:K23) -> -78.781513 | L19: dBm
A20: OTA
A21: OTA | B21: SDR Max Gain (SDR-24 amplifier card) | C21: 90 | D21: dB | F21: Physical attenuator, SDR-to-ERA | G21: =C26 -> -1e-06 | H21: dB | J21: Physical attenuator, SDR-to-ERA | K21: =G21 -> -1e-06 | L21: dB
B22: SDR DL ALC set point | C22: =COMMISSIONING!D25 -> 13 | D22: dBm | E22: OPT! | F22: Cable loss, SDR-to-ERA | G22: =C27 -> -6 | H22: dB | J22: Cable loss, SDR-to-ERA | K22: =G22 -> -6 | L22: dB
B23: DL Gain (dynamically set by ALC)(<90dB) | C23: =MIN(C22-C19,C21) -> 90 | D23: dB | F23: UL TSSI out of RFD Port | G23: =SUM(G25:G27) -> -52.010299 | H23: dBm | J23: UL Noise power out of RFD Port | K23: =SUM(K28:K29)+SUM(K25:K26) -> -72.781512 | L23: dBm
B24: DL Signal after SDR (AGC set point) | C24: =C19+C23 -> 11.542425 | D24: dBm
F25: ERA System Uplink Gain (from below box) | G25: =G40 -> 20.447276 | H25: dB | J25: ERA System Uplink Gain | K25: =G25 -> 20.447276 | L25: dB
B26: Physical attenuator, SDR-to-ERA | C26: =COMMISSIONING!D45 -> -1e-06 | D26: dB | E26: OPT! | J26: Number of CAPMs (dB) | K26: =10*LOG(K27) -> 3.0103 | L26: dB
A27: SDR | B27: Cable loss, SDR-to-ERA | C27: =COMMISSIONING!D46 -> -6 | D27: dB | E27: Check | F27: UL RSSI at CAPM | G27: =SUM(G28:G29) -> -72.457575 | H27: dBm | J27: Number of CAPMs | K27: =COMMISSIONING!D41 -> 2 | L27: #
A28: SDR | B28: DL Signal into ERA RFD port | C28: =SUM(C24,C26:C27) -> 5.5424241 | D28: dBm | F28: Pathloss + DAS Loss, UE to CAPM | G28: =C33 -> -96.457575 | H28: dB | J28: NF of CAPM | K28: =COMMISSIONING!D50 -> 6 | L28: dB
A29: SDR | F29: EIRP from UE | G29: =COMMISSIONING!D48 -> 24 | H29: dBm | J29: Thermal Noise of CAPM in channel | K29: =-174 + 10*LOG(C6)+60 -> -102.23909 | L29: dBm
B30: DL composite Tx power /channel @ CAPM | C30: =MIN(C28+36,27) -> 27 | D30: dBm | E30: Check
A31: ERA | B31: DL Gain (dynamically set by Auto Gain Setting) | C31: =C30-C28 -> 21.457576 | D31: dB
A32: ERA | I32: OPT!
A33: ERA | B33: Passive DAS loss + Pathloss to UE | C33: =COMMISSIONING!D47 -> -96.457575 | D33: dB | F33: Calculation of ERA System Uplink Gain: | J33: Calculation of DAS noise's impact on BTS noise floor:
A34: ERA | B34: Max composite channel RSSI at UE | C34: =C30+C33 -> -69.457575 | D34: dBm
A35: ERA | B35: RSRP at UE | C35: =C34-C12 -> -99 | D35: dBm RSRP | F35: ERA RFD Uplink Gain Offset Setting [integer] | G35: =COMMISSIONING!D32 -> 2 | H35: dB | J35: BTS Thermal Noise in channel | K35: =K29 -> -102.23909 | L35: dBm
A36: ERA | F36: ERA CAN Reduction = 10.Log(#APs) | G36: =-10*LOG(G37) -> -3.0103 | H36: dB | J36: BTS NF | K36: =COMMISSIONING!D49 -> 0 | L36: dB
F37: ERA Number of CAPMs [integer] | G37: =COMMISSIONING!D41 -> 2 | H37: # | J37: BTS Noise Floor | K37: =SUM(K35:K36) -> -102.23909 | L37: dBm
F38: ERA Baseline UL Gain = DL Gain | G38: =C31 -> 21.457576 | H38: dB
J39: DAS UL RSSI at BTS radio | K39: =K7 -> -108.25969 | L39: dBm
F40: ERA System Uplink Gain | G40: =G38+G36+G35 -> 20.447276 | H40: dB | J40: BTS Noise Floor with DAS UL Noise | K40: =10*LOG(10^(K37/10)+10^(K39/10)) -> -101.26999 | L40: dBm
J42: Noise Rise at BTS due to DAS | K42: =K40-K37 -> 0.96910013 | L42: dB

Sheet Bellus 2600
A1: Costco DAS Link Budgets -- Off-Air, ADRF SDR and CommScope ERA | G1: -2 | H1: Reference value
B3: DOWNLINK | F3: UPLINK Signal (worst case) | J3: NOISE
A4: Index | B4: Item | C4: Value | D4: Unit | G4: Value | H4: Unit | K4: Value | L4: Unit
A5: OTA | B5: Band & Technology | C5: =COMMISSIONING!E7 -> LTE-2600 | J5: Noise Rise at BTS due to DAS | K5: =K42 -> 0.96910013 | L5: dB
A6: OTA | B6: Channel BW | C6: =COMMISSIONING!E8 -> 20 | D6: MHz | F6: Recommended UL Gain Offset: | G6: =(K37-6)-K39+G35 -> 2.0205999 | H6: dB
A7: OTA | B7: BTS radio Tx Power, comp. channel power | C7: 40 | D7: W | J7: UL Noise Power at Donor sector BTS radio | K7: =K12+K14+K15 -> -107.0103 | L7: dBm
A8: OTA | B8: BTS radio Tx Power, comp. channel power | C8: =10*LOG(C7)+30 -> 46.0206 | D8: dBm | F8: Max possible UL SINR (not considering traffic) | G8: =G9-K37 -> 5.7506126 | H8: dB
A9: OTA | F9: UL RSSI at Donor sector BTS radio | G9: =G12+G14+G15 -> -95.239087 | H9: dBm
A10: OTA | B10: Donor RSRP in donor cable (head-end room) | C10: =COMMISSIONING!E11 -> -90 | D10: dBm RSRP
A11: OTA
A12: OTA | B12: RSRP to max RSSI conversion factor | C12: =10*LOG(60*C6) -> 30.791812 | D12: dB | F12: Pathloss, H.E.R. to Donor sector radio | G12: =C14 -> -105.22879 | H12: dB | J12: Pathloss, H.E.R. to Donor sector radio | K12: =G12 -> -105.22879 | L12: dB
A13: OTA | B13: Max donor RSSI in donor cable (comp. ch pwr) | C13: =C12+C10 -> -59.208188 | D13: dBm RSSI
A14: OTA | B14: Pathloss, Donor sector radio to H.E.R. | C14: =-(C8-C13) -> -105.22879 | D14: dB | F14: Physical attenuator on SDR | G14: =C18 -> -20 | H14: dB | J14: Physical attenuator on SDR amp Donor port | K14: =G14 -> -20 | L14: dB
A15: OTA | F15: UL composite channel power out of SDR | G15: =SUM(G18:G19) -> 29.9897 | H15: dBm | J15: UL Noise power out of SDR | K15: =SUM(K17:K19) -> 18.218487 | L15: dBm
A16: OTA | B16: TARGET DL Signal going into SDR (RSSI) | C16: =C22-C21+2 -> -75 | D16: dBm
A17: OTA | B17: Required PHYS attenuation before SDR amp | C17: =ROUND(C16-C13,0) -> -16 | D17: dB | J17: SDR NF | K17: =COMMISSIONING!E51 -> 5 | L17: dB
A18: OTA | B18: Actual PHYS attenuation before SDR amp | C18: =COMMISSIONING!E15 -> -20 | D18: dB | F18: SDR UL Gain (same as DL, set by AGC) | G18: =C23 -> 90 | H18: dBm | J18: SDR UL Gain (same as DL, set by AGC) | K18: =G18 -> 90 | L18: dBm
A19: OTA | B19: EXPECTED DL Signal going into SDR (RSSI) | C19: =C13+C18 -> -79.208188 | D19: dBm | F19: UL composite channel power into SDR | G19: =SUM(G20:G23) -> -60.0103 | H19: dBm | J19: UL Noise power into SDR | K19: =SUM(K20:K23) -> -76.781513 | L19: dBm
A20: OTA
A21: OTA | B21: SDR Max Gain (SDR-24 amplifier card) | C21: 90 | D21: dB | F21: Physical attenuator, SDR-to-ERA | G21: =C26 -> -1e-06 | H21: dB | J21: Physical attenuator, SDR-to-ERA | K21: =G21 -> -1e-06 | L21: dB
B22: SDR DL AGC set point | C22: =COMMISSIONING!E25 -> 13 | D22: dBm | E22: OPT! | F22: Cable loss, SDR-to-ERA | G22: =C27 -> -6 | H22: dB | J22: Cable loss, SDR-to-ERA | K22: =G22 -> -6 | L22: dB
B23: DL Gain (dynamically set by AGC)(<90dB) | C23: =MIN(C22-C19,C21) -> 90 | D23: dB | F23: UL TSSI out of RFD Port | G23: =SUM(G25:G27) -> -54.010299 | H23: dBm | J23: UL Noise power out of RFD Port | K23: =SUM(K28:K29)+SUM(K25:K26) -> -70.781512 | L23: dBm
B24: DL Signal after SDR (AGC set point) | C24: =C19+C23 -> 10.791812 | D24: dBm
F25: ERA System Uplink Gain (from below box) | G25: =G40 -> 21.197889 | H25: dB | J25: ERA System Uplink Gain | K25: =G25 -> 21.197889 | L25: dB
B26: Physical attenuator, SDR-to-ERA | C26: =COMMISSIONING!E45 -> -1e-06 | D26: dB | E26: OPT! | J26: Number of CAPMs (dB) | K26: =10*LOG(K27) -> 3.0103 | L26: dB
A27: SDR | B27: Cable loss, SDR-to-ERA | C27: =COMMISSIONING!E46 -> -6 | D27: dB | E27: Check | F27: UL RSSI at CAPM | G27: =SUM(G28:G29) -> -75.208188 | H27: dBm | J27: Number of CAPMs | K27: =COMMISSIONING!E41 -> 2 | L27: #
A28: SDR | B28: DL Signal into ERA RFD port | C28: =SUM(C24,C26:C27) -> 4.7918115 | D28: dBm | F28: Pathloss + DAS Loss, UE to CAPM | G28: =C33 -> -99.208188 | H28: dB | J28: NF of CAPM | K28: =COMMISSIONING!E50 -> 6 | L28: dB
A29: SDR | F29: EIRP from UE | G29: =COMMISSIONING!E48 -> 24 | H29: dBm | J29: Thermal Noise of CAPM in channel | K29: =-174 + 10*LOG(C6)+60 -> -100.9897 | L29: dBm
B30: DL composite Tx power /channel @ CAPM | C30: =MIN(C28+36,27) -> 27 | D30: dBm | E30: Check
A31: ERA | B31: DL Gain (dynamically set by Auto Gain Setting) | C31: =C30-C28 -> 22.208189 | D31: dB
A32: ERA | I32: OPT!
A33: ERA | B33: Passive DAS loss + Pathloss to UE | C33: =COMMISSIONING!E47 -> -99.208188 | D33: dB | F33: Calculation of ERA System Uplink Gain: | J33: Calculation of DAS noise's impact on BTS noise floor:
A34: ERA | B34: Max composite channel RSSI at UE | C34: =C30+C33 -> -72.208188 | D34: dBm
A35: ERA | B35: RSRP at UE | C35: =C34-C12 -> -103 | D35: dBm RSRP | F35: ERA RFD Uplink Gain Offset Setting [integer] | G35: =COMMISSIONING!E32 -> 2 | H35: dB | J35: BTS Thermal Noise in channel | K35: =K29 -> -100.9897 | L35: dBm
A36: ERA | F36: ERA CAN Reduction = 10.Log(#APs) | G36: =-10*LOG(G37) -> -3.0103 | H36: dB | J36: BTS NF | K36: =COMMISSIONING!E49 -> 0 | L36: dB
F37: ERA Number of CAPMs [integer] | G37: =COMMISSIONING!E41 -> 2 | H37: # | J37: BTS Noise Floor | K37: =SUM(K35:K36) -> -100.9897 | L37: dBm
F38: ERA Baseline UL Gain = DL Gain | G38: =C31 -> 22.208189 | H38: dB
J39: DAS UL RSSI at BTS radio | K39: =K7 -> -107.0103 | L39: dBm
F40: ERA System Uplink Gain | G40: =G38+G36+G35 -> 21.197889 | H40: dB | J40: BTS Noise Floor with DAS UL Noise | K40: =10*LOG(10^(K37/10)+10^(K39/10)) -> -100.0206 | L40: dBm
J42: Noise Rise at BTS due to DAS | K42: =K40-K37 -> 0.96910013 | L42: dB

Sheet Rogers 1900
A1: Costco DAS Link Budgets -- Off-Air, ADRF SDR and CommScope ERA | G1: -2 | H1: Reference value
B3: DOWNLINK | F3: UPLINK Signal (worst case) | J3: NOISE
A4: Index | B4: Item | C4: Value | D4: Unit | G4: Value | H4: Unit | K4: Value | L4: Unit
A5: OTA | B5: Band & Technology | C5: =COMMISSIONING!C55 -> LTE-1900 | J5: Noise Rise at BTS due to DAS | K5: =K42 -> 0.63610789 | L5: dB
A6: OTA | B6: Channel BW | C6: =COMMISSIONING!C56 -> 15 | D6: MHz | F6: Recommended UL Gain Offset: | G6: =-108-K39 -> 2.2596873 | H6: dB
A7: OTA | B7: BTS radio Tx Power, comp. channel power | C7: 40 | D7: W | J7: UL Noise Power at Donor sector BTS radio | K7: =K12+K14+K15 -> -110.25969 | L7: dBm
A8: OTA | B8: BTS radio Tx Power, comp. channel power | C8: =10*LOG(C7)+30 -> 46.0206 | D8: dBm | F8: Max possible UL SINR (not considering traffic) | G8: =G9-K37 -> 10 | H8: dB
A9: OTA | F9: UL RSSI at Donor sector BTS radio | G9: =G12+G14+G15 -> -92.239087 | H9: dBm
A10: OTA | B10: Donor RSRP in donor cable (head-end room) | C10: =COMMISSIONING!C59 -> 0 | D10: dBm RSRP
A11: OTA
A12: OTA | B12: RSRP to max RSSI conversion factor | C12: =10*LOG(60*C6) -> 29.542425 | D12: dB | F12: Pathloss, H.E.R. to Donor sector radio | G12: =C14 -> -16.478175 | H12: dB | J12: Pathloss, H.E.R. to Donor sector radio | K12: =G12 -> -16.478175 | L12: dB
A13: OTA | B13: Max donor RSSI in donor cable (comp. ch pwr) | C13: =C12+C10 -> 29.542425 | D13: dBm RSSI
A14: OTA | B14: Pathloss, Donor sector radio to H.E.R. | C14: =-(C8-C13) -> -16.478175 | D14: dB | F14: Physical attenuator on SDR | G14: =C18 -> -20 | H14: dB | J14: Physical attenuator on SDR amp Donor port | K14: =G14 -> -20 | L14: dB
A15: OTA | F15: UL composite channel power out of SDR | G15: =SUM(G18:G19) -> -55.760913 | H15: dBm | J15: UL Noise power out of SDR | K15: =SUM(K17:K19) -> -73.781513 | L15: dBm
A16: OTA | B16: TARGET DL Signal going into SDR (RSSI) | C16: =C22-C21+2 -> -78 | D16: dBm
A17: OTA | B17: Required PHYS attenuation before SDR amp | C17: =ROUND(C16-C13,0) -> -108 | D17: dB | J17: SDR NF | K17: =COMMISSIONING!C51 -> 5 | L17: dB
A18: OTA | B18: Actual PHYS attenuation before SDR amp | C18: =COMMISSIONING!C63 -> -20 | D18: dB | F18: SDR UL Gain (same as DL, set by AGC) | G18: =C23 -> 0.45757491 | H18: dBm | J18: SDR UL Gain (same as DL, set by AGC) | K18: =G18 -> 0.45757491 | L18: dBm
A19: OTA | B19: EXPECTED DL Signal going into SDR (RSSI) | C19: =C13+C18 -> 9.5424251 | D19: dBm | F19: UL composite channel power into SDR | G19: =SUM(G20:G23) -> -56.218487 | H19: dBm | J19: UL Noise power into SDR | K19: =SUM(K20:K23) -> -79.239087 | L19: dBm
A20: OTA
A21: OTA | B21: SDR Max Gain (SDR-24 amplifier card) | C21: 90 | D21: dB | F21: Physical attenuator, SDR-to-ERA | G21: =C26 -> -1e-06 | H21: dB | J21: Physical attenuator, SDR-to-ERA | K21: =G21 -> -1e-06 | L21: dB
B22: SDR DL AGC set point | C22: =COMMISSIONING!C66 -> 10 | D22: dBm | E22: OPT! | F22: Cable loss, SDR-to-ERA | G22: =C27 -> -6 | H22: dB | J22: Cable loss, SDR-to-ERA | K22: =G22 -> -6 | L22: dB
B23: DL Gain (dynamically set by AGC)(<90dB) | C23: =MIN(C22-C19,C21) -> 0.45757491 | D23: dB | F23: UL TSSI out of RFD Port | G23: =SUM(G25:G27) -> -50.218486 | H23: dBm | J23: UL Noise power out of RFD Port | K23: =SUM(K28:K29)+SUM(K25:K26) -> -73.239086 | L23: dBm
B24: DL Signal after SDR (AGC set point) | C24: =C19+C23 -> 10 | D24: dBm
F25: ERA System Uplink Gain (from below box) | G25: =G40 -> 19.989701 | H25: dB | J25: ERA System Uplink Gain | K25: =G25 -> 19.989701 | L25: dB
B26: Physical attenuator, SDR-to-ERA | C26: =COMMISSIONING!C81 -> -1e-06 | D26: dB | E26: OPT! | J26: Number of CAPMs (dB) | K26: =10*LOG(K27) -> 3.0103 | L26: dB
A27: SDR | B27: SDR-to-ERA loss (cable, combining, etc.) | C27: =COMMISSIONING!C46 -> -6 | D27: dB | E27: Check | F27: UL RSSI at CAPM | G27: =SUM(G28:G29) -> -70.208188 | H27: dBm | J27: Number of CAPMs | K27: =COMMISSIONING!C41 -> 2 | L27: #
A28: SDR | B28: DL Signal into ERA RFD port | C28: =SUM(C24,C26:C27) -> 3.999999 | D28: dBm | F28: Pathloss + DAS Loss, UE to CAPM | G28: =C33 -> -94.208188 | H28: dB | J28: NF of CAPM | K28: =COMMISSIONING!C50 -> 6 | L28: dB
A29: SDR | F29: EIRP from UE | G29: =COMMISSIONING!C48 -> 24 | H29: dBm | J29: Thermal Noise of CAPM in channel | K29: =-174 + 10*LOG(C6)+60 -> -102.23909 | L29: dBm
B30: DL composite Tx power /channel @ CAPM | C30: =MIN(C28+36,27) -> 27 | D30: dBm | E30: Check
A31: ERA | B31: DL Gain (dynamically set by Auto Gain Setting) | C31: =C30-C28 -> 23.000001 | D31: dB
A32: ERA | I32: OPT!
A33: ERA | B33: Passive DAS loss + Pathloss to UE | C33: =COMMISSIONING!C47 -> -94.208188 | D33: dB | F33: Calculation of ERA System Uplink Gain: | J33: Calculation of DAS noise's impact on BTS noise floor:
A34: ERA | B34: Max composite channel RSSI at UE | C34: =C30+C33 -> -67.208188 | D34: dBm
A35: ERA | B35: RSRP at UE | C35: =C34-C12 -> -96.750613 | D35: dBm RSRP | F35: ERA RFD Uplink Gain Offset Setting [integer] | G35: =COMMISSIONING!C70 -> 0 | H35: dB | J35: BTS Thermal Noise in channel | K35: =K29 -> -102.23909 | L35: dBm
A36: ERA | F36: ERA CAN Reduction = 10.Log(#APs) | G36: =-10*LOG(G37) -> -3.0103 | H36: dB | J36: BTS NF | K36: =COMMISSIONING!C85 -> 0 | L36: dB
F37: ERA Number of CAPMs [integer] | G37: =COMMISSIONING!C41 -> 2 | H37: # | J37: BTS Noise Floor | K37: =SUM(K35:K36) -> -102.23909 | L37: dBm
F38: ERA Baseline UL Gain = DL Gain | G38: =C31 -> 23.000001 | H38: dB
J39: DAS UL RSSI at BTS radio | K39: =K7 -> -110.25969 | L39: dBm
F40: ERA System Uplink Gain | G40: =G38+G36+G35 -> 19.989701 | H40: dB | J40: BTS Noise Floor with DAS UL Noise | K40: =10*LOG(10^(K37/10)+10^(K39/10)) -> -101.60298 | L40: dBm
J42: Noise Rise at BTS due to DAS | K42: =K40-K37 -> 0.63610789 | L42: dB

Sheet Rogers 2100
A1: Costco DAS Link Budgets -- Off-Air, ADRF SDR and CommScope ERA | G1: -2 | H1: Reference value
B3: DOWNLINK | F3: UPLINK Signal (worst case) | J3: NOISE
A4: Index | B4: Item | C4: Value | D4: Unit | G4: Value | H4: Unit | K4: Value | L4: Unit
A5: OTA | B5: Band & Technology | C5: =COMMISSIONING!D55 -> LTE-2100 | J5: Noise Rise at BTS due to DAS | K5: =K42 -> 0.63610789 | L5: dB
A6: OTA | B6: Channel BW | C6: =COMMISSIONING!D56 -> 15 | D6: MHz | F6: Recommended UL Gain Offset: | G6: =-106-K39 -> 4.2596873 | H6: dB
A7: OTA | B7: BTS radio Tx Power, comp. channel power | C7: 40 | D7: W | J7: UL Noise Power at Donor sector BTS radio | K7: =K12+K14+K15 -> -110.25969 | L7: dBm
A8: OTA | B8: BTS radio Tx Power, comp. channel power | C8: =10*LOG(C7)+30 -> 46.0206 | D8: dBm | F8: Max possible UL SINR (not considering traffic) | G8: =G9-K37 -> 7.7506126 | H8: dB
A9: OTA | F9: UL RSSI at Donor sector BTS radio | G9: =G12+G14+G15 -> -94.488475 | H9: dBm
A10: OTA | B10: Donor RSRP in donor cable (head-end room) | C10: =COMMISSIONING!D59 -> 0 | D10: dBm RSRP
A11: OTA
A12: OTA | B12: RSRP to max RSSI conversion factor | C12: =10*LOG(60*C6) -> 29.542425 | D12: dB | F12: Pathloss, H.E.R. to Donor sector radio | G12: =C14 -> -16.478175 | H12: dB | J12: Pathloss, H.E.R. to Donor sector radio | K12: =G12 -> -16.478175 | L12: dB
A13: OTA | B13: Max donor RSSI in donor cable (comp. ch pwr) | C13: =C12+C10 -> 29.542425 | D13: dBm RSSI
A14: OTA | B14: Pathloss, Donor sector radio to H.E.R. | C14: =-(C8-C13) -> -16.478175 | D14: dB | F14: Physical attenuator on SDR | G14: =C18 -> -20 | H14: dB | J14: Physical attenuator on SDR amp Donor port | K14: =G14 -> -20 | L14: dB
A15: OTA | F15: UL composite channel power out of SDR | G15: =SUM(G18:G19) -> -58.0103 | H15: dBm | J15: UL Noise power out of SDR | K15: =SUM(K17:K19) -> -73.781513 | L15: dBm
A16: OTA | B16: TARGET DL Signal going into SDR (RSSI) | C16: =C22-C21+2 -> -78 | D16: dBm
A17: OTA | B17: Required PHYS attenuation before SDR amp | C17: =ROUND(C16-C13,0) -> -108 | D17: dB | J17: SDR NF | K17: =COMMISSIONING!D51 -> 5 | L17: dB
A18: OTA | B18: Actual PHYS attenuation before SDR amp | C18: =COMMISSIONING!D63 -> -20 | D18: dB | F18: SDR UL Gain (same as DL, set by AGC) | G18: =C23 -> 0.45757491 | H18: dBm | J18: SDR UL Gain (same as DL, set by AGC) | K18: =G18 -> 0.45757491 | L18: dBm
A19: OTA | B19: EXPECTED DL Signal going into SDR (RSSI) | C19: =C13+C18 -> 9.5424251 | D19: dBm | F19: UL composite channel power into SDR | G19: =SUM(G20:G23) -> -58.467875 | H19: dBm | J19: UL Noise power into SDR | K19: =SUM(K20:K23) -> -79.239087 | L19: dBm
A20: OTA
A21: OTA | B21: SDR Max Gain (SDR-24 amplifier card) | C21: 90 | D21: dB | F21: Physical attenuator, SDR-to-ERA | G21: =C26 -> -1e-06 | H21: dB | J21: Physical attenuator, SDR-to-ERA | K21: =G21 -> -1e-06 | L21: dB
B22: SDR DL AGC set point | C22: =COMMISSIONING!D66 -> 10 | D22: dBm | E22: OPT! | F22: Cable loss, SDR-to-ERA | G22: =C27 -> -6 | H22: dB | J22: Cable loss, SDR-to-ERA | K22: =G22 -> -6 | L22: dB
B23: DL Gain (dynamically set by AGC)(<90dB) | C23: =MIN(C22-C19,C21) -> 0.45757491 | D23: dB | F23: UL TSSI out of RFD Port | G23: =SUM(G25:G27) -> -52.467874 | H23: dBm | J23: UL Noise power out of RFD Port | K23: =SUM(K28:K29)+SUM(K25:K26) -> -73.239086 | L23: dBm
B24: DL Signal after SDR (AGC set point) | C24: =C19+C23 -> 10 | D24: dBm
F25: ERA System Uplink Gain (from below box) | G25: =G40 -> 19.989701 | H25: dB | J25: ERA System Uplink Gain | K25: =G25 -> 19.989701 | L25: dB
B26: Physical attenuator, SDR-to-ERA | C26: =COMMISSIONING!D81 -> -1e-06 | D26: dB | E26: OPT! | J26: Number of CAPMs (dB) | K26: =10*LOG(K27) -> 3.0103 | L26: dB
A27: SDR | B27: Cable loss, SDR-to-ERA | C27: =COMMISSIONING!D46 -> -6 | D27: dB | E27: Check | F27: UL RSSI at CAPM | G27: =SUM(G28:G29) -> -72.457575 | H27: dBm | J27: Number of CAPMs | K27: =COMMISSIONING!D41 -> 2 | L27: #
A28: SDR | B28: DL Signal into ERA RFD port | C28: =SUM(C24,C26:C27) -> 3.999999 | D28: dBm | F28: Pathloss + DAS Loss, UE to CAPM | G28: =C33 -> -96.457575 | H28: dB | J28: NF of CAPM | K28: =COMMISSIONING!D50 -> 6 | L28: dB
A29: SDR | F29: EIRP from UE | G29: =COMMISSIONING!D48 -> 24 | H29: dBm | J29: Thermal Noise of CAPM in channel | K29: =-174 + 10*LOG(C6)+60 -> -102.23909 | L29: dBm
B30: DL composite Tx power /channel @ CAPM | C30: =MIN(C28+36,27) -> 27 | D30: dBm | E30: Check
A31: ERA | B31: DL Gain (dynamically set by Auto Gain Setting) | C31: =C30-C28 -> 23.000001 | D31: dB
A32: ERA | I32: OPT!
A33: ERA | B33: Passive DAS loss + Pathloss to UE | C33: =COMMISSIONING!D47 -> -96.457575 | D33: dB | F33: Calculation of ERA System Uplink Gain: | J33: Calculation of DAS noise's impact on BTS noise floor:
A34: ERA | B34: Max composite channel RSSI at UE | C34: =C30+C33 -> -69.457575 | D34: dBm
A35: ERA | B35: RSRP at UE | C35: =C34-C12 -> -99 | D35: dBm RSRP | F35: ERA RFD Uplink Gain Offset Setting [integer] | G35: =COMMISSIONING!D70 -> 0 | H35: dB | J35: BTS Thermal Noise in channel | K35: =K29 -> -102.23909 | L35: dBm
A36: ERA | F36: ERA CAN Reduction = 10.Log(#APs) | G36: =-10*LOG(G37) -> -3.0103 | H36: dB | J36: BTS NF | K36: =COMMISSIONING!D85 -> 0 | L36: dB
F37: ERA Number of CAPMs [integer] | G37: =COMMISSIONING!D41 -> 2 | H37: # | J37: BTS Noise Floor | K37: =SUM(K35:K36) -> -102.23909 | L37: dBm
F38: ERA Baseline UL Gain = DL Gain | G38: =C31 -> 23.000001 | H38: dB
J39: DAS UL RSSI at BTS radio | K39: =K7 -> -110.25969 | L39: dBm
F40: ERA System Uplink Gain | G40: =G38+G36+G35 -> 19.989701 | H40: dB | J40: BTS Noise Floor with DAS UL Noise | K40: =10*LOG(10^(K37/10)+10^(K39/10)) -> -101.60298 | L40: dBm
J42: Noise Rise at BTS due to DAS | K42: =K40-K37 -> 0.63610789 | L42: dB

Sheet Rogers 2600
A1: Costco DAS Link Budgets -- Off-Air, ADRF SDR and CommScope ERA | G1: -2 | H1: Reference value
B3: DOWNLINK | F3: UPLINK Signal (worst case) | J3: NOISE
A4: Index | B4: Item | C4: Value | D4: Unit | G4: Value | H4: Unit | K4: Value | L4: Unit
A5: OTA | B5: Band & Technology | C5: =COMMISSIONING!E55 -> LTE-2600 | J5: Noise Rise at BTS due to DAS | K5: =K42 -> 0.63610789 | L5: dB
A6: OTA | B6: Channel BW | C6: =COMMISSIONING!E56 -> 20 | D6: MHz | F6: Recommended UL Gain Offset: | G6: =-106-K39 -> 3.0103 | H6: dB
A7: OTA | B7: BTS radio Tx Power, comp. channel power | C7: 40 | D7: W | J7: UL Noise Power at Donor sector BTS radio | K7: =K12+K14+K15 -> -109.0103 | L7: dBm
A8: OTA | B8: BTS radio Tx Power, comp. channel power | C8: =10*LOG(C7)+30 -> 46.0206 | D8: dBm | F8: Max possible UL SINR (not considering traffic) | G8: =G9-K37 -> 3.7506126 | H8: dB
A9: OTA | F9: UL RSSI at Donor sector BTS radio | G9: =G12+G14+G15 -> -97.239087 | H9: dBm
A10: OTA | B10: Donor RSRP in donor cable (head-end room) | C10: =COMMISSIONING!E59 -> 0 | D10: dBm RSRP
A11: OTA
A12: OTA | B12: RSRP to max RSSI conversion factor | C12: =10*LOG(60*C6) -> 30.791812 | D12: dB | F12: Pathloss, H.E.R. to Donor sector radio | G12: =C14 -> -15.228787 | H12: dB | J12: Pathloss, H.E.R. to Donor sector radio | K12: =G12 -> -15.228787 | L12: dB
A13: OTA | B13: Max donor RSSI in donor cable (comp. ch pwr) | C13: =C12+C10 -> 30.791812 | D13: dBm RSSI
A14: OTA | B14: Pathloss, Donor sector radio to H.E.R. | C14: =-(C8-C13) -> -15.228787 | D14: dB | F14: Physical attenuator on SDR | G14: =C18 -> -16 | H14: dB | J14: Physical attenuator on SDR amp Donor port | K14: =G14 -> -16 | L14: dB
A15: OTA | F15: UL composite channel power out of SDR | G15: =SUM(G18:G19) -> -66.0103 | H15: dBm | J15: UL Noise power out of SDR | K15: =SUM(K17:K19) -> -77.781513 | L15: dBm
A16: OTA | B16: TARGET DL Signal going into SDR (RSSI) | C16: =C22-C21+2 -> -78 | D16: dBm
A17: OTA | B17: Required PHYS attenuation before SDR amp | C17: =ROUND(C16-C13,0) -> -109 | D17: dB | J17: SDR NF | K17: =COMMISSIONING!E51 -> 5 | L17: dB
A18: OTA | B18: Actual PHYS attenuation before SDR amp | C18: =COMMISSIONING!E63 -> -16 | D18: dB | F18: SDR UL Gain (same as DL, set by AGC) | G18: =C23 -> -4.7918125 | H18: dBm | J18: SDR UL Gain (same as DL, set by AGC) | K18: =G18 -> -4.7918125 | L18: dBm
A19: OTA | B19: EXPECTED DL Signal going into SDR (RSSI) | C19: =C13+C18 -> 14.791812 | D19: dBm | F19: UL composite channel power into SDR | G19: =SUM(G20:G23) -> -61.218487 | H19: dBm | J19: UL Noise power into SDR | K19: =SUM(K20:K23) -> -77.9897 | L19: dBm
A20: OTA
A21: OTA | B21: SDR Max Gain (SDR-24 amplifier card) | C21: 90 | D21: dB | F21: Physical attenuator, SDR-to-ERA | G21: =C26 -> -1e-06 | H21: dB | J21: Physical attenuator, SDR-to-ERA | K21: =G21 -> -1e-06 | L21: dB
B22: SDR DL AGC set point | C22: =COMMISSIONING!E66 -> 10 | D22: dBm | E22: OPT! | F22: Cable loss, SDR-to-ERA | G22: =C27 -> -6 | H22: dB | J22: Cable loss, SDR-to-ERA | K22: =G22 -> -6 | L22: dB
B23: DL Gain (dynamically set by AGC)(<90dB) | C23: =MIN(C22-C19,C21) -> -4.7918125 | D23: dB | F23: UL TSSI out of RFD Port | G23: =SUM(G25:G27) -> -55.218486 | H23: dBm | J23: UL Noise power out of RFD Port | K23: =SUM(K28:K29)+SUM(K25:K26) -> -71.989699 | L23: dBm
B24: DL Signal after SDR (AGC set point) | C24: =C19+C23 -> 10 | D24: dBm
F25: ERA System Uplink Gain (from below box) | G25: =G40 -> 19.989701 | H25: dB | J25: ERA System Uplink Gain | K25: =G25 -> 19.989701 | L25: dB
B26: Physical attenuator, SDR-to-ERA | C26: =COMMISSIONING!E81 -> -1e-06 | D26: dB | E26: OPT! | J26: Number of CAPMs (dB) | K26: =10*LOG(K27) -> 3.0103 | L26: dB
A27: SDR | B27: Cable loss, SDR-to-ERA | C27: =COMMISSIONING!E46 -> -6 | D27: dB | E27: Check | F27: UL RSSI at CAPM | G27: =SUM(G28:G29) -> -75.208188 | H27: dBm | J27: Number of CAPMs | K27: =COMMISSIONING!E41 -> 2 | L27: #
A28: SDR | B28: DL Signal into ERA RFD port | C28: =SUM(C24,C26:C27) -> 3.999999 | D28: dBm | F28: Pathloss + DAS Loss, UE to CAPM | G28: =C33 -> -99.208188 | H28: dB | J28: NF of CAPM | K28: =COMMISSIONING!E50 -> 6 | L28: dB
A29: SDR | F29: EIRP from UE | G29: =COMMISSIONING!E48 -> 24 | H29: dBm | J29: Thermal Noise of CAPM in channel | K29: =-174 + 10*LOG(C6)+60 -> -100.9897 | L29: dBm
B30: DL composite Tx power /channel @ CAPM | C30: =MIN(C28+36,27) -> 27 | D30: dBm | E30: Check
A31: ERA | B31: DL Gain (dynamically set by Auto Gain Setting) | C31: =C30-C28 -> 23.000001 | D31: dB
A32: ERA | I32: OPT!
A33: ERA | B33: Passive DAS loss + Pathloss to UE | C33: =COMMISSIONING!E47 -> -99.208188 | D33: dB | F33: Calculation of ERA System Uplink Gain: | J33: Calculation of DAS noise's impact on BTS noise floor:
A34: ERA | B34: Max composite channel RSSI at UE | C34: =C30+C33 -> -72.208188 | D34: dBm
A35: ERA | B35: RSRP at UE | C35: =C34-C12 -> -103 | D35: dBm RSRP | F35: ERA RFD Uplink Gain Offset Setting [integer] | G35: =COMMISSIONING!E70 -> 0 | H35: dB | J35: BTS Thermal Noise in channel | K35: =K29 -> -100.9897 | L35: dBm
A36: ERA | F36: ERA CAN Reduction = 10.Log(#APs) | G36: =-10*LOG(G37) -> -3.0103 | H36: dB | J36: BTS NF | K36: =COMMISSIONING!E85 -> 0 | L36: dB
F37: ERA Number of CAPMs [integer] | G37: =COMMISSIONING!E41 -> 2 | H37: # | J37: BTS Noise Floor | K37: =SUM(K35:K36) -> -100.9897 | L37: dBm
F38: ERA Baseline UL Gain = DL Gain | G38: =C31 -> 23.000001 | H38: dB
J39: DAS UL RSSI at BTS radio | K39: =K7 -> -109.0103 | L39: dBm
F40: ERA System Uplink Gain | G40: =G38+G36+G35 -> 19.989701 | H40: dB | J40: BTS Noise Floor with DAS UL Noise | K40: =10*LOG(10^(K37/10)+10^(K39/10)) -> -100.35359 | L40: dBm
J42: Noise Rise at BTS due to DAS | K42: =K40-K37 -> 0.63610789 | L42: dB

Sheet Revisions
A1: Revision Control Table
A3: Date | B3: Version | C3: Description | D3: Author | E3: Reviewer
A4: 45863 | B4: 1.2 | C4: Added EXPECTATIONS and COMMISSIONING tabs. Reviewed all with Phil, David, Andrew, Haitham, Boris, Ali. | D4: John Willson | E4: Ali Talebian
A5: 45867 | B5: 1.3 | C5: Separated UL noise calc's into ERA and SDR noise. Added space for commissioners to record measured UL noise. Added headings to COMMISSIONING page for clarity. | D5: John Willson
A6: 45867 | B6: 1.4 | C6: Added calculations for a second operator. | D6: John Willson
A7: 45888 | B7: 1.5 | C7: Added PCI to EXPECTATIONS tab. | D7: John Willson | E7: Ali Talebian
A8: 45904 | B8: 1.6 | C8: -Corrected C30 from "+19" to "+36" because ERA max DL gain is 36 dB. -Updated "UL Gain Offset" recommendation so the value doesn't change with actual UL Gain Offset. | D8: John Willson | E8: Phil Spatafora
